<?xml version="1.0" encoding="utf-8"?>
<robot name="Mobile_Leveling_Platform_V2">


<!--link color-->
  <gazebo reference="beacon_link">
      <material>Gazebo/Green</material> 
  </gazebo>

  <gazebo reference="GPS_link">
      <material>Gazebo/Black</material> 
  </gazebo>


<!-- base_link mass :15.686-->

  <link
    name="base_link">
    <inertial>
      <origin
        xyz="0 0 0"
        rpy="0 0 0" />
      <mass
        value="15.686" />
      <inertia
        ixx="3.1779"
        ixy="0"
        ixz="0"
        iyy="3.6754"
        iyz="0"
        izz="4.4975" />
    </inertial>
    <visual>
      <origin
        xyz="0 1.5 0"
        rpy="0 0 0" />
      <geometry>
        <mesh
          filename="package://Mobile_Leveling_Platform_V2/meshes/base_link.STL" />
      </geometry>
      <material
        name="">
        <color
          rgba="0.82353 0.82353 1 1" />
      </material>
    </visual>
    <collision>
      <origin
        xyz="0 0 0"
        rpy="0 0 0" />
      <geometry>
	<box size="0.64 0.998 0.222"/>
      </geometry>
    </collision>
  </link>

  <joint
    name="imu_base_joint"
    type="fixed">
    <origin
      xyz="0 0 0.111"
      rpy="0 0 0" />
    <parent
      link="base_link" />
    <child
      link="imu_link_base" />
    <axis
      xyz="0 0 0" />
  </joint>

  <link name ="imu_link_base">
    <inertial>
      <origin
        xyz="0 0 0" 
        rpy="0 0 0" />
      <mass
        value="0.1" />
      <inertia
        ixx="0.000001667"
        ixy="0"
        ixz="0"
        iyy="0.000001667"
        iyz="0"
        izz="0.000001667" />
    </inertial>
    <visual>
      <origin
        xyz="0 0 0"
        rpy="0 0 0" />
      <geometry>
	<box size = "0.01 0.01 0.01"/>
      </geometry>
      <material
        name="">
        <color
          rgba="0.82353 0.82353 1 1" />
      </material>
    </visual>
    <collision>
      <origin
        xyz="0 0 0"
        rpy="0 0 0" />
      <geometry>
	<box size = "0.01 0.01 0.01"/>
      </geometry>
    </collision>
  </link>
  <link
    name="front_L_motor_rev_link">
    <inertial>
      <origin
        xyz="0 0 0"
        rpy="0 0 0" />
      <mass
        value="0.075717" />
      <inertia
        ixx="3.7606E-05"
        ixy="1.0136E-07"
        ixz="-5.7378E-07"
        iyy="3.7419E-05"
        iyz="-1.7765E-07"
        izz="3.9868E-05" />
    </inertial>
    <visual>
      <origin
        xyz="0 0 0"
        rpy="0 0 0" />
      <geometry>
        <mesh
          filename="package://Mobile_Leveling_Platform_V2/meshes/front_L_motor_rev_link.STL" />
      </geometry>
      <material
        name="">
        <color
          rgba="0.82353 0.82353 1 1" />
      </material>
    </visual>
    <collision>
      <origin
        xyz="0 0 0"
        rpy="0 0 0" />
      <geometry>
        <mesh
          filename="package://Mobile_Leveling_Platform_V2/meshes/front_L_motor_rev_link.STL" />
      </geometry>
    </collision>
  </link>
  <joint
    name="front_L_motor_rev_joint"
    type="continuous">
    <origin
      xyz="0.363 -0.3709 -0.041791"
      rpy="0 -1.5708 0" />
    <parent
      link="base_link" />
    <child
      link="front_L_motor_rev_link" />
    <axis
      xyz="0 0 -1" />
  </joint>
  <link
    name="front_L_tire_link">
    <inertial>
      <origin
        xyz="0 0 0"
        rpy="0 0 0" />
      <mass
        value="2.9551" />
      <inertia
        ixx="0.029016"
        ixy="0"
        ixz="0"
        iyy="0.015583"
        iyz="0"
        izz="0.015587" />
    </inertial>
    <visual>
      <origin
        xyz="0 0 0"
        rpy="0 0 0" />
      <geometry>
        <mesh
          filename="package://Mobile_Leveling_Platform_V2/meshes/front_L_tire_link.STL" />
      </geometry>
      <material
        name="">
        <color
          rgba="0.82353 0.82353 1 1" />
      </material>
    </visual>
    <collision>
      <origin
        xyz="0 0 0"
        rpy="0 0 0" />
      <geometry>
        <mesh
          filename="package://Mobile_Leveling_Platform_V2/meshes/front_L_tire_link.STL" />
      </geometry>
    </collision>
  </link>
  <joint
    name="front_L_tire_joint"
    type="fixed">
    <origin
      xyz="0 0 -0.011"
      rpy="0.13209 1.5708 0" />
    <parent
      link="front_L_motor_rev_link" />
    <child
      link="front_L_tire_link" />
    <axis
      xyz="0 0 0" />
  </joint>
  <link
    name="front_R_motor_link">
    <inertial>
      <origin
        xyz="0 0 0"
        rpy="0 0 0" />
      <mass
        value="0.075717" />
      <inertia
        ixx="3.7606E-05"
        ixy="1.0136E-07"
        ixz="-5.7378E-07"
        iyy="3.7419E-05"
        iyz="-1.7765E-07"
        izz="3.9868E-05" />
    </inertial>
    <visual>
      <origin
        xyz="0 0 0"
        rpy="0 0 0" />
      <geometry>
        <mesh
          filename="package://Mobile_Leveling_Platform_V2/meshes/front_R_motor_link.STL" />
      </geometry>
      <material
        name="">
        <color
          rgba="0.82353 0.82353 1 1" />
      </material>
    </visual>
    <collision>
      <origin
        xyz="0 0 0"
        rpy="0 0 0" />
      <geometry>
        <mesh
          filename="package://Mobile_Leveling_Platform_V2/meshes/front_R_motor_link.STL" />
      </geometry>
    </collision>
  </link>
  <joint
    name="front_R_motor_rev_joint"
    type="continuous">
    <origin
      xyz="-0.363 -0.3709 -0.041791"
      rpy="3.1416 -1.5708 0" />
    <parent
      link="base_link" />
    <child
      link="front_R_motor_link" />
    <axis
      xyz="0 0 1" />
  </joint>
  <link
    name="front_R_tire_link">
    <inertial>
      <origin
        xyz="0 0 0"
        rpy="0 0 0" />
      <mass
        value="2.9551" />
      <inertia
        ixx="0.029016"
        ixy="0"
        ixz="0"
        iyy="0.015583"
        iyz="0"
        izz="0.015587" />
    </inertial>
    <visual>
      <origin
        xyz="0 0 0"
        rpy="0 0 0" />
      <geometry>
        <mesh
          filename="package://Mobile_Leveling_Platform_V2/meshes/front_R_tire_link.STL" />
      </geometry>
      <material
        name="">
        <color
          rgba="0.82353 0.82353 1 1" />
      </material>
    </visual>
    <collision>
      <origin
        xyz="0 0 0"
        rpy="0 0 0" />
      <geometry>
        <mesh
          filename="package://Mobile_Leveling_Platform_V2/meshes/front_R_tire_link.STL" />
      </geometry>
    </collision>
  </link>
  <joint
    name="front_R_tire_joint"
    type="fixed">
    <origin
      xyz="0 0 -0.011"
      rpy="0.14726 1.5708 0" />
    <parent
      link="front_R_motor_link" />
    <child
      link="front_R_tire_link" />
    <axis
      xyz="0 0 0" />
  </joint>
  <link
    name="rear_L_motor_rev_link">
    <inertial>
      <origin
        xyz="0 0 0"
        rpy="0 0 0" />
      <mass
        value="0.075717" />
      <inertia
        ixx="3.7606E-05"
        ixy="1.0136E-07"
        ixz="-5.7378E-07"
        iyy="3.7419E-05"
        iyz="-1.7765E-07"
        izz="3.9868E-05" />
    </inertial>
    <visual>
      <origin
        xyz="0 0 0"
        rpy="0 0 0" />
      <geometry>
        <mesh
          filename="package://Mobile_Leveling_Platform_V2/meshes/rear_L_motor_rev_link.STL" />
      </geometry>
      <material
        name="">
        <color
          rgba="0.82353 0.82353 1 1" />
      </material>
    </visual>
    <collision>
      <origin
        xyz="0 0 0"
        rpy="0 0 0" />
      <geometry>
        <mesh
          filename="package://Mobile_Leveling_Platform_V2/meshes/rear_L_motor_rev_link.STL" />
      </geometry>
    </collision>
  </link>
  <joint
    name="rear_L_motor_rev_joint"
    type="continuous">
    <origin
      xyz="0.363 0.3731 -0.041791"
      rpy="0 -1.5708 0" />
    <parent
      link="base_link" />
    <child
      link="rear_L_motor_rev_link" />
    <axis
      xyz="0 0 -1" />
  </joint>
  <link
    name="rear_L_tire_link">
    <inertial>
      <origin
        xyz="0 0 0"
        rpy="0 0 0" />
      <mass
        value="2.9551" />
      <inertia
        ixx="0.029016"
        ixy="0"
        ixz="0"
        iyy="0.015583"
        iyz="0"
        izz="0.015587" />
    </inertial>
    <visual>
      <origin
        xyz="0 0 0"
        rpy="0 0 0" />
      <geometry>
        <mesh
          filename="package://Mobile_Leveling_Platform_V2/meshes/rear_L_tire_link.STL" />
      </geometry>
      <material
        name="">
        <color
          rgba="0.82353 0.82353 1 1" />
      </material>
    </visual>
    <collision>
      <origin
        xyz="0 0 0"
        rpy="0 0 0" />
      <geometry>
        <mesh
          filename="package://Mobile_Leveling_Platform_V2/meshes/rear_L_tire_link.STL" />
      </geometry>
    </collision>
  </link>
  <joint
    name="rear_L_tire_joint"
    type="fixed">
    <origin
      xyz="0 0 -0.011"
      rpy="0.13537 -1.5708 0" />
    <parent
      link="rear_L_motor_rev_link" />
    <child
      link="rear_L_tire_link" />
    <axis
      xyz="0 0 0" />
  </joint>
  <link
    name="rear_R_motor_rev_link">
    <inertial>
      <origin
        xyz="0 0 0"
        rpy="0 0 0" />
      <mass
        value="0.075717" />
      <inertia
        ixx="3.7606E-05"
        ixy="1.0136E-07"
        ixz="-5.7378E-07"
        iyy="3.7419E-05"
        iyz="-1.7765E-07"
        izz="3.9868E-05" />
    </inertial>
    <visual>
      <origin
        xyz="0 0 0"
        rpy="0 0 0" />
      <geometry>
        <mesh
          filename="package://Mobile_Leveling_Platform_V2/meshes/rear_R_motor_rev_link.STL" />
      </geometry>
      <material
        name="">
        <color
          rgba="0.82353 0.82353 1 1" />
      </material>
    </visual>
    <collision>
      <origin
        xyz="0 0 0"
        rpy="0 0 0" />
      <geometry>
        <mesh
          filename="package://Mobile_Leveling_Platform_V2/meshes/rear_R_motor_rev_link.STL" />
      </geometry>
    </collision>
  </link>
  <joint
    name="rear_R_motor_rev_joint"
    type="continuous">
    <origin
      xyz="-0.363 0.3731 -0.041791"
      rpy="3.1416 -1.5708 0" />
    <parent
      link="base_link" />
    <child
      link="rear_R_motor_rev_link" />
    <axis
      xyz="0 0 1" />
  </joint>
  <link
    name="rear_R_tire_link">
    <inertial>
      <origin
        xyz="0 0 0"
        rpy="0 0 0" />
      <mass
        value="2.9551" />
      <inertia
        ixx="0.029016"
        ixy="0"
        ixz="0"
        iyy="0.015583"
        iyz="0"
        izz="0.015587" />
    </inertial>
    <visual>
      <origin
        xyz="0 0 0"
        rpy="0 0 0" />
      <geometry>
        <mesh
          filename="package://Mobile_Leveling_Platform_V2/meshes/rear_R_tire_link.STL" />
      </geometry>
      <material
        name="">
        <color
          rgba="0.82353 0.82353 1 1" />
      </material>
    </visual>
    <collision>
      <origin
        xyz="0 0 0"
        rpy="0 0 0" />
      <geometry>
        <mesh
          filename="package://Mobile_Leveling_Platform_V2/meshes/rear_R_tire_link.STL" />
      </geometry>
    </collision>
  </link>
  <joint
    name="rear_R_tire_joint"
    type="fixed">
    <origin
      xyz="0 0 -0.011"
      rpy="0.1395 1.5708 0" />
    <parent
      link="rear_R_motor_rev_link" />
    <child
      link="rear_R_tire_link" />
    <axis
      xyz="0 0 0" />
  </joint>-->
  <link
    name="mating_link">
    <inertial>
      <origin
        xyz="0.28001 -0.915 -0.041642"
        rpy="0 0 0" />
      <mass
        value="15" /> <!--mating_link_ mass:14.754-->
      <inertia
        ixx="4.107625"
        ixy="0"
        ixz="0"
        iyy="0.5245"
        iyz="0"
        izz="4.607125" />
    </inertial>
    <visual>
      <origin
        xyz="0 0 0" 
        rpy="0 0 0" />
      <geometry>
        <mesh
          filename="package://Mobile_Leveling_Platform_V2/meshes/mating_link.STL" />
      </geometry>
      <material
        name="">
        <color
          rgba="0.82353 0.82353 1 1" />
      </material>
    </visual>
    <collision>
      <origin
        xyz="0.28001 -0.915 -0.041642" 
        rpy="0 0 0" />
      <geometry>
	<box size="0.64 1.810 0.1"/>
      </geometry>
    </collision>
  </link>
  <joint
    name="mating_joint"
    type="fixed">
    <origin
      xyz="-0.28 0.88511 0.20249"
      rpy="0 0 0" />
    <parent
      link="base_link" />
    <child
      link="mating_link" />
    <axis
      xyz="0 0 0" />
  </joint>
  <link
    name="front_leveling_link">
    <inertial>
      <origin
        xyz="-0.094 -0.0078388 0.49881"
        rpy="0 0 0" />
      <mass
        value="1.9876" />
      <inertia
        ixx="0.025468"
        ixy="0"
        ixz="0"
        iyy="0.024479"
        iyz="0"
        izz="0.0026287" />
    </inertial>
    <visual>
      <origin
        xyz="0 0 0"
        rpy="0 0 0" />
      <geometry>
        <mesh
          filename="package://Mobile_Leveling_Platform_V2/meshes/front_leveling_link.STL" />
      </geometry>
      <material
        name="">
        <color
          rgba="0.82353 0.82353 1 1" />
      </material>
    </visual>
    <collision>
      <origin
        xyz="-0.1 -0.03 0.355"
        rpy="0 0 0" />
      <geometry>
	<box size = "0.218 0.153 0.697"/>
      </geometry>
    </collision>
  </link>
  <joint
    name="front_leveling_joint"
    type="fixed">
    <origin
      xyz="0.374 -1.768 0.015"
      rpy="0 0 0" />
    <parent
      link="mating_link" />
    <child
      link="front_leveling_link" />
    <axis
      xyz="0 0 0" />
  </joint>
  <link
    name="front_motor_rev_link">
    <inertial>
      <origin
        xyz="9.7145E-16 0.030907 2.2204E-16"
        rpy="0 0 0" />
      <mass
        value="0.025329" /> 
      <inertia
        ixx="6.8991E-06"
        ixy="-2.7437E-22"
        ixz="3.1069E-40"
        iyy="1.0461E-05"
        iyz="1.7456E-23"
        izz="6.8991E-06" />
    </inertial>
    <visual>
      <origin
        xyz="0 0 0"
        rpy="0 0 0" />
      <geometry>
        <mesh
          filename="package://Mobile_Leveling_Platform_V2/meshes/front_motor_rev_link.STL" />
      </geometry>
      <material
        name="">
        <color
          rgba="0.82353 0.82353 1 1" />
      </material>
    </visual>
    <collision>
      <origin
        xyz="0 0 0"
        rpy="0 0 0" />
      <geometry>
        <mesh
          filename="package://Mobile_Leveling_Platform_V2/meshes/front_motor_rev_link.STL" />
      </geometry>
    </collision>
  </link>
  <joint
    name="GPS_joint"
    type="fixed">
    <origin
      xyz="9.7145E-16 0.030907 0.0095"
      rpy="0 3.141592 0" />
    <parent
      link="front_motor_rev_link" />
    <child
      link="GPS_link" />
    <axis
      xyz="0 0 0" />
  </joint>
  <link 
    name="GPS_link">
    <inertial>
      <origin
        xyz="9.7145E-16 0.030907 0.015" 
        rpy="0 3.141592 0" />
      <mass
        value="0.1" />
      <inertia
        ixx="0.000001667"
        ixy="0"
        ixz="0"
        iyy="0.000001667"
        iyz="0"
        izz="0.000001667" />
    </inertial>
    <visual>
      <origin
        xyz="9.7145E-16 0.030907 0.015"
        rpy="0 3.141592 0" />
      <geometry>
	<box size = "0.01 0.01 0.01"/>
      </geometry>
      <material
        name="">
        <color
          rgba="0.82353 0.82353 1 1" />
      </material>
    </visual>
    <collision>
      <origin
        xyz="9.7145E-16 0.030907 0.015"
        rpy="0 3.141592 0" />
      <geometry>
	<box size = "0.01 0.01 0.01"/>
      </geometry>
    </collision>
  </link>
  <joint
    name="front_motor_rev_joint"
    type="revolute">

    <origin
      xyz="-0.094 0.055 0.67"
      rpy="3.1416 0 -3.1416" />
    <parent
      link="front_leveling_link" />
    <child
      link="front_motor_rev_link" />
    <axis
      xyz="0 1 0" />
    <limit
      lower="-0.5236"
      upper="0.5236"
      effort="1"
      velocity="1" />
  </joint>

  <link
    name="under_upper_link">
    <inertial>
      <origin
        xyz="0.0862 0.80081 -0.32342"
        rpy="0.017453289 0 0" />
      <mass
        value="8.5158" />
      <inertia
        ixx="1.146358675"
        ixy="0"
        ixz="0"
        iyy="1.146358675"
        iyz="0"
        izz="1.930760367" />
    </inertial>
    <visual>
      <origin
        xyz="0 0 0"
        rpy="0 0 0" />
      <geometry>
        <mesh
          filename="package://Mobile_Leveling_Platform_V2/meshes/under_upper_link.STL" />
      </geometry>
      <material
        name="">
        <color
          rgba="0.82353 0.82353 1 1" />
      </material>
    </visual>
    <collision>
      <origin
        xyz="0.0862 0.80081 -0.32342"
        rpy="0 0 0" />
      <geometry>
        <box size="1.166345146172 1.166345146172 0.505" />
      </geometry>
    </collision>
  </link>



  <joint
    name="under_upper_joint"
    type="fixed">
    <origin
      xyz="0.087597 0.053 0.015743"
      rpy="-3.1416 0 -3.1416" />
    <parent
      link="front_motor_rev_link" />
    <child
      link="under_upper_link" />
    <axis
      xyz="0 0 0" />
  </joint>
  <link
    name="upper_motor_rev_link">
    <inertial>
      <origin
        xyz="-2.2204E-16 0.030907 1.1102E-16"
        rpy="0 0 0" />
      <mass
        value="0.025329" />
      <inertia
        ixx="6.8991E-06"
        ixy="5.9833E-22"
        ixz="-5.5917E-22"
        iyy="1.0461E-05"
        iyz="1.757E-23"
        izz="6.8991E-06" />
    </inertial>
    <visual>
      <origin
        xyz="0 0 0"
        rpy="0 0 0" />
      <geometry>
        <mesh
          filename="package://Mobile_Leveling_Platform_V2/meshes/upper_motor_rev_link.STL" />
      </geometry>
      <material
        name="">
        <color
          rgba="0.82353 0.82353 1 1" />
      </material>
    </visual>
    <collision>
      <origin
        xyz="0 0 0"
        rpy="0 0 0" />
      <geometry>
        <mesh
          filename="package://Mobile_Leveling_Platform_V2/meshes/upper_motor_rev_link.STL" />
      </geometry>
    </collision>
  </link>
  <joint
    name="upper_motor_rev_joint"
    type="revolute">
    <origin
      xyz="0.877 0.79375 0"
      rpy="0 -0.0058456 1.5708" />
    <parent
      link="under_upper_link" />
    <child
      link="upper_motor_rev_link" />
    <axis
      xyz="0 -1 0" />
    <limit
      lower="-0.5236"
      upper="0.5236"
      effort="1"
      velocity="1" />
  </joint>
  <link
    name="upper_link">
    <inertial>
      <origin
        xyz="-0.00040832 -0.00031982 -0.0067744"
        rpy="0 0 0" />
      <mass
        value="12.075" />
      <inertia
        ixx="2.264968125"
        ixy="0"
        ixz="0"
        iyy="2.264968125"
        iyz="0"
        izz="4.528125" />
    </inertial>
    <visual>
      <origin
        xyz="0 0 0"
        rpy="0 0 0" />
      <geometry>
        <mesh
          filename="package://Mobile_Leveling_Platform_V2/meshes/upper.STL" />
      </geometry>
      <material
        name="">
        <color
          rgba="0.82353 0.82353 1 1" />
      </material>
    </visual>
    <collision>
      <origin
        xyz="-0.00040832 -0.00031982 -0.0067744"
        rpy="0 0 0" />
      <geometry>
        <box size="1.5 1.5 0.03" />
      </geometry>
    </collision>
  </link>

  <joint
    name="beacon_joint"
    type="fixed">
    <origin
      xyz="-0.00040832 -0.00031982 0.004"

      rpy="0 0 0" />
    <parent
      link="upper_link" />
    <child
      link="beacon_link" />
    <axis
      xyz="0 0 0" />
  </joint>
  <link name="beacon_link">
    <inertial>
      <mass value="10.0"/>
      <origin rpy="0  0  0" xyz="0 0 0"/>
      <inertia ixx="0.01" ixy="0" ixz="0" iyy="0.01" iyz="0" izz="0.01"/>
    </inertial>
    <collision name="beacon_collision">
      <origin rpy="0  0  0" xyz="0.00040832 -0.00031982 0.005"/>
      <geometry>
        <box size="0.1 0.1 0.01"/>
      </geometry>
    </collision>
    <visual name="beacon_visual">
      <origin rpy="0  0  0" xyz="0.00040832 -0.00031982 0.005"/>
      <geometry>
        <box size="0.1 0.1 0.02"/>
      </geometry>
    </visual>
  </link>

  <joint
    name="upper_joint"
    type="fixed">
    <origin
      xyz="0.0038376 0.788 0.014978"
      rpy="-0.0058456 0 -1.5708" />
    <parent
      link="upper_motor_rev_link" />
    <child
      link="upper_link" />
    <axis
      xyz="0 0 0" />
  </joint>

  <link name ="imu_link_upper">
    <inertial>
      <origin
        xyz="-0.00040832 -0.00031982 -0.02"
        rpy="0 0 0" />
      <mass
        value="0.1" />
      <inertia
        ixx="0.000001667"
        ixy="0"
        ixz="0"
        iyy="0.000001667"
        iyz="0"
        izz="0.000001667" />
    </inertial>
    <visual>
      <origin
        xyz="-0.00040832 -0.00031982 -0.02"
        rpy="0 0 0" />
      <geometry>
	<box size = "0.01 0.01 0.01"/>
      </geometry>
      <material
        name="">
        <color
          rgba="255 255 255" />
      </material>
    </visual>
    <collision>
      <origin
        xyz="-0.00040832 -0.00031982 -0.02"
        rpy="0 0 0" />
      <geometry>
	<box size = "0.01 0.01 0.01"/>  
      </geometry>
    </collision>
  </link>

  <joint
    name="imu_joint"
    type="fixed">
    <origin
      xyz="-0.00040832 -0.00031982 -0.015"
      rpy="0 0 0" />
    <parent
      link="upper_link" />
    <child
      link="imu_link_upper" />
    <axis
      xyz="0 0 0" />
  </joint>
  <link
    name="rear_Leveling_link">
    <inertial>
      <origin
        xyz="0.03175 -0.0029488 0.36"
        rpy="0 0 0" />
      <mass
        value="2.75" />
      <inertia
        ixx="0.025468"
        ixy="0"
        ixz="0"
        iyy="0.024479"
        iyz="0"
        izz="0.0026287" />
    </inertial>
    <visual>
      <origin
        xyz="0 0 0"
        rpy="0 0 0" />
      <geometry>
        <mesh
          filename="package://Mobile_Leveling_Platform_V2/meshes/rear_Leveling_link.STL" />
      </geometry>
      <material
        name="">
        <color
          rgba="0.82353 0.82353 1 1" />
      </material>
    </visual>
    <collision>
      <origin
        xyz="0.03175 -0.0029488 0.36"
        rpy="0 0 0" />
      <geometry>
	<box size="0.1535 0.080 0.697"/>
      </geometry>
    </collision>
  </link>
  <joint
    name="rear_Leveling_joint"
    type="fixed">
    <origin
      xyz="0.24825 0 0.015"
      rpy="0 0 0" />
    <parent
      link="mating_link" />
    <child
      link="rear_Leveling_link" />
    <axis
      xyz="0 0 0" />
  </joint>



</robot>
