
<sdf version='1.6'>
  <model name='Mobile_Leveling_Platform_V2'>
    <link name='base_link'>
      <pose frame=''>0 0 0 0 -0 0</pose>
      <inertial>
        <pose frame=''>4e-06 0.005832 0.153015 0 -0 0</pose>
        <mass>35.5236</mass>
        <inertia>
          <ixx>12.5602</ixx>
          <ixy>5.35833e-06</ixy>
          <ixz>-1.17498e-06</ixz>
          <iyy>5.74336</iyy>
          <iyz>-0.0289936</iyz>
          <izz>12.8391</izz>
        </inertia>
      </inertial>
      <collision name='base_link_collision'>
        <pose frame=''>0 0 0 0 -0 0</pose>
        <geometry>
          <box>
            <size>0.64 0.998 0.222</size>
          </box>
        </geometry>
      </collision>
      <collision name='base_link_fixed_joint_lump__imu_link_base_collision_1'>
        <pose frame=''>0 0 0.111 0 -0 0</pose>
        <geometry>
          <box>
            <size>0.01 0.01 0.01</size>
          </box>
        </geometry>
      </collision>
      <collision name='base_link_fixed_joint_lump__mating_link_collision_2'>
        <pose frame=''>1e-05 -0.02989 0.160848 0 -0 0</pose>
        <geometry>
          <box>
            <size>0.64 1.81 0.1</size>
          </box>
        </geometry>
      </collision>
      <collision name='base_link_fixed_joint_lump__front_leveling_link_collision_3'>
        <pose frame=''>-0.006 -0.91289 0.57249 0 -0 0</pose>
        <geometry>
          <box>
            <size>0.218 0.153 0.697</size>
          </box>
        </geometry>
      </collision>
      <collision name='base_link_fixed_joint_lump__rear_Leveling_link_collision_4'>
        <pose frame=''>0 0.882161 0.57749 0 -0 0</pose>
        <geometry>
          <box>
            <size>0.1535 0.08 0.697</size>
          </box>
        </geometry>
      </collision>
      <visual name='base_link_visual'>
        <pose frame=''>0 1.5 0 0 -0 0</pose>
        <geometry>
          <mesh>
            <scale>1 1 1</scale>
            <uri>model://Mobile_Leveling_Platform_V2/meshes/base_link.STL</uri>
          </mesh>
        </geometry>
      </visual>
      <visual name='base_link_fixed_joint_lump__imu_link_base_visual_1'>
        <pose frame=''>0 0 0.111 0 -0 0</pose>
        <geometry>
          <box>
            <size>0.01 0.01 0.01</size>
          </box>
        </geometry>
      </visual>
      <visual name='base_link_fixed_joint_lump__mating_link_visual_2'>
        <pose frame=''>-0.28 0.88511 0.20249 0 -0 0</pose>
        <geometry>
          <mesh>
            <scale>1 1 1</scale>
            <uri>model://Mobile_Leveling_Platform_V2/meshes/mating_link.STL</uri>
          </mesh>
        </geometry>
      </visual>
      <visual name='base_link_fixed_joint_lump__front_leveling_link_visual_3'>
        <pose frame=''>0.094 -0.88289 0.21749 0 -0 0</pose>
        <geometry>
          <mesh>
            <scale>1 1 1</scale>
            <uri>model://Mobile_Leveling_Platform_V2/meshes/front_leveling_link.STL</uri>
          </mesh>
        </geometry>
      </visual>
      <visual name='base_link_fixed_joint_lump__rear_Leveling_link_visual_4'>
        <pose frame=''>-0.03175 0.88511 0.21749 0 -0 0</pose>
        <geometry>
          <mesh>
            <scale>1 1 1</scale>
            <uri>model://Mobile_Leveling_Platform_V2/meshes/rear_Leveling_link.STL</uri>
          </mesh>
        </geometry>
      </visual>
    </link>
    <link name='front_L_motor_rev_link'>
      <pose frame=''>0.363 -0.3709 -0.041791 3.14159 -1.57079 3.14159</pose>
      <inertial>
        <pose frame=''>0 0 -0.010725 0 -0 0</pose>
        <mass>3.03082</mass>
        <inertia>
          <ixx>0.0156335</ixx>
          <ixy>-4.20874e-07</ixy>
          <ixz>-5.7378e-07</ixz>
          <iyy>0.0156294</iyy>
          <iyz>-1.7765e-07</iyz>
          <izz>0.0290559</izz>
        </inertia>
      </inertial>
      <collision name='front_L_motor_rev_link_collision'>
        <pose frame=''>0 0 0 0 -0 0</pose>
        <geometry>
          <mesh>
            <scale>1 1 1</scale>
            <uri>model://Mobile_Leveling_Platform_V2/meshes/front_L_motor_rev_link.STL</uri>
          </mesh>
        </geometry>
      </collision>
      <collision name='front_L_motor_rev_link_fixed_joint_lump__front_L_tire_link_collision_1'>
        <pose frame=''>0 0 -0.011 3.14159 1.57079 3.0095</pose>
        <geometry>
          <mesh>
            <scale>1 1 1</scale>
            <uri>model://Mobile_Leveling_Platform_V2/meshes/front_L_tire_link.STL</uri>
          </mesh>
        </geometry>
      </collision>
      <visual name='front_L_motor_rev_link_visual'>
        <pose frame=''>0 0 0 0 -0 0</pose>
        <geometry>
          <mesh>
            <scale>1 1 1</scale>
            <uri>model://Mobile_Leveling_Platform_V2/meshes/front_L_motor_rev_link.STL</uri>
          </mesh>
        </geometry>
      </visual>
      <visual name='front_L_motor_rev_link_fixed_joint_lump__front_L_tire_link_visual_1'>
        <pose frame=''>0 0 -0.011 3.14159 1.57079 3.0095</pose>
        <geometry>
          <mesh>
            <scale>1 1 1</scale>
            <uri>model://Mobile_Leveling_Platform_V2/meshes/front_L_tire_link.STL</uri>
          </mesh>
        </geometry>
      </visual>
    </link>
    <joint name='front_L_motor_rev_joint' type='revolute'>
      <child>front_L_motor_rev_link</child>
      <parent>base_link</parent>
      <axis>
        <xyz>1 0 4e-06</xyz>
        <limit>
          <lower>-1e+16</lower>
          <upper>1e+16</upper>
        </limit>
        <dynamics>
          <spring_reference>0</spring_reference>
          <spring_stiffness>0</spring_stiffness>
        </dynamics>
        <use_parent_model_frame>1</use_parent_model_frame>
      </axis>
    </joint>
    <link name='front_R_motor_link'>
      <pose frame=''>-0.363 -0.3709 -0.041791 7e-06 -1.57079 -3.14159</pose>
      <inertial>
        <pose frame=''>0 0 -0.010725 0 -0 0</pose>
        <mass>3.03082</mass>
        <inertia>
          <ixx>0.0156335</ixx>
          <ixy>-4.79199e-07</ixy>
          <ixz>-5.7378e-07</ixz>
          <iyy>0.0156294</iyy>
          <iyz>-1.7765e-07</iyz>
          <izz>0.0290559</izz>
        </inertia>
      </inertial>
      <collision name='front_R_motor_link_collision'>
        <pose frame=''>0 0 0 0 -0 0</pose>
        <geometry>
          <mesh>
            <scale>1 1 1</scale>
            <uri>model://Mobile_Leveling_Platform_V2/meshes/front_R_motor_link.STL</uri>
          </mesh>
        </geometry>
      </collision>
      <collision name='front_R_motor_link_fixed_joint_lump__front_R_tire_link_collision_1'>
        <pose frame=''>0 0 -0.011 3.14159 1.57079 2.99433</pose>
        <geometry>
          <mesh>
            <scale>1 1 1</scale>
            <uri>model://Mobile_Leveling_Platform_V2/meshes/front_R_tire_link.STL</uri>
          </mesh>
        </geometry>
      </collision>
      <visual name='front_R_motor_link_visual'>
        <pose frame=''>0 0 0 0 -0 0</pose>
        <geometry>
          <mesh>
            <scale>1 1 1</scale>
            <uri>model://Mobile_Leveling_Platform_V2/meshes/front_R_motor_link.STL</uri>
          </mesh>
        </geometry>
      </visual>
      <visual name='front_R_motor_link_fixed_joint_lump__front_R_tire_link_visual_1'>
        <pose frame=''>0 0 -0.011 3.14159 1.57079 2.99433</pose>
        <geometry>
          <mesh>
            <scale>1 1 1</scale>
            <uri>model://Mobile_Leveling_Platform_V2/meshes/front_R_tire_link.STL</uri>
          </mesh>
        </geometry>
      </visual>
    </link>
    <joint name='front_R_motor_rev_joint' type='revolute'>
      <child>front_R_motor_link</child>
      <parent>base_link</parent>
      <axis>
        <xyz>1 7e-06 4e-06</xyz>
        <limit>
          <lower>-1e+16</lower>
          <upper>1e+16</upper>
        </limit>
        <dynamics>
          <spring_reference>0</spring_reference>
          <spring_stiffness>0</spring_stiffness>
        </dynamics>
        <use_parent_model_frame>1</use_parent_model_frame>
      </axis>
    </joint>
    <link name='front_motor_rev_link'>
      <pose frame=''>0 -0.82789 0.88749 -3.14159 -0 3.14159</pose>
      <inertial>
        <pose frame=''>0.001383 0.842231 0.334186 0 -0 0</pose>
        <mass>8.64113</mass>
        <inertia>
          <ixx>1.23967</ixx>
          <ixy>-0.00013831</ixy>
          <ixz>-5.9428e-05</ixz>
          <iyy>1.16119</iyy>
          <iyz>-0.0201866</iyz>
          <izz>2.00925</izz>
        </inertia>
      </inertial>
      <collision name='front_motor_rev_link_collision'>
        <pose frame=''>0 0 0 0 -0 0</pose>
        <geometry>
          <mesh>
            <scale>1 1 1</scale>
            <uri>model://Mobile_Leveling_Platform_V2/meshes/front_motor_rev_link.STL</uri>
          </mesh>
        </geometry>
      </collision>
      <collision name='front_motor_rev_link_fixed_joint_lump__GPS_link_collision_1'>
        <pose frame=''>0 0.061814 -0.0055 0 -1e-06 0</pose>
        <geometry>
          <box>
            <size>0.01 0.01 0.01</size>
          </box>
        </geometry>
        <surface>
          <contact>
            <ode/>
          </contact>
          <friction>
            <ode/>
          </friction>
        </surface>
      </collision>
      <collision name='front_motor_rev_link_fixed_joint_lump__under_upper_link_collision_2'>
        <pose frame=''>0.001403 0.853808 0.339169 3.14159 -0 3.14159</pose>
        <geometry>
          <box>
            <size>1.16635 1.16635 0.505</size>
          </box>
        </geometry>
      </collision>
      <visual name='front_motor_rev_link_visual'>
        <pose frame=''>0 0 0 0 -0 0</pose>
        <geometry>
          <mesh>
            <scale>1 1 1</scale>
            <uri>model://Mobile_Leveling_Platform_V2/meshes/front_motor_rev_link.STL</uri>
          </mesh>
        </geometry>
      </visual>
      <visual name='front_motor_rev_link_fixed_joint_lump__GPS_link_visual_1'>
        <pose frame=''>0 0.061814 -0.0055 0 -1e-06 0</pose>
        <geometry>
          <box>
            <size>0.01 0.01 0.01</size>
          </box>
        </geometry>
        <material>
          <script>
            <name>Gazebo/Black</name>
            <uri>file://media/materials/scripts/gazebo.material</uri>
          </script>
        </material>
      </visual>
      <visual name='front_motor_rev_link_fixed_joint_lump__under_upper_link_visual_2'>
        <pose frame=''>0.087597 0.053 0.015743 3.14159 -0 3.14159</pose>
        <geometry>
          <mesh>
            <scale>1 1 1</scale>
            <uri>model://Mobile_Leveling_Platform_V2/meshes/under_upper_link.STL</uri>
          </mesh>
        </geometry>
      </visual>
      <gravity>1</gravity>
      <velocity_decay/>
    </link>
    <joint name='front_motor_rev_joint' type='revolute'>
      <child>front_motor_rev_link</child>
      <parent>base_link</parent>
      <axis>
        <xyz>7e-06 1 -7e-06</xyz>
        <limit>
          <lower>-0.5236</lower>
          <upper>0.5236</upper>
          <effort>1</effort>
          <velocity>1</velocity>
        </limit>
        <dynamics>
          <spring_reference>0</spring_reference>
          <spring_stiffness>0</spring_stiffness>
        </dynamics>
        <use_parent_model_frame>1</use_parent_model_frame>
      </axis>
    </joint>
    <link name='upper_motor_rev_link'>
      <pose frame=''>0.789403 0.018861 0.871735 0 -0.005831 1.5708</pose>
      <inertial>
        <pose frame=''>0.0035 0.787546 0.012922 0 -0 0</pose>
        <mass>22.2003</mass>
        <inertia>
          <ixx>2.29032</ixx>
          <ixy>-6.7141e-05</ixy>
          <ixz>0.0132227</ixz>
          <iyy>2.27573</iyy>
          <iyz>-0.00024664</iyz>
          <izz>4.55257</izz>
        </inertia>
      </inertial>
      <collision name='upper_motor_rev_link_collision'>
        <pose frame=''>0 0 0 0 -0 0</pose>
        <geometry>
          <mesh>
            <scale>1 1 1</scale>
            <uri>model://Mobile_Leveling_Platform_V2/meshes/upper_motor_rev_link.STL</uri>
          </mesh>
        </geometry>
      </collision>
      <collision name='upper_motor_rev_link_fixed_joint_lump__upper_link_collision_1'>
        <pose frame=''>0.003478 0.788408 0.008206 -0.005846 -0 -1.5708</pose>
        <geometry>
          <box>
            <size>1.5 1.5 0.03</size>
          </box>
        </geometry>
      </collision>
      <collision name='upper_motor_rev_link_fixed_joint_lump__beacon_collision_collision_2'>
        <pose frame=''>0.003251 0.788 0.023982 -0.005846 -0 -1.5708</pose>
        <geometry>
          <box>
            <size>0.1 0.1 0.01</size>
          </box>
        </geometry>
      </collision>
      <collision name='upper_motor_rev_link_fixed_joint_lump__imu_link_upper_collision_3'>
        <pose frame=''>0.002993 0.788817 -0.020018 -0.005846 -0 -1.5708</pose>
        <geometry>
          <box>
            <size>0.01 0.01 0.01</size>
          </box>
        </geometry>
      </collision>
      <visual name='upper_motor_rev_link_visual'>
        <pose frame=''>0 0 0 0 -0 0</pose>
        <geometry>
          <mesh>
            <scale>1 1 1</scale>
            <uri>model://Mobile_Leveling_Platform_V2/meshes/upper_motor_rev_link.STL</uri>
          </mesh>
        </geometry>
      </visual>
      <visual name='upper_motor_rev_link_fixed_joint_lump__upper_link_visual_1'>
        <pose frame=''>0.003838 0.788 0.014978 -0.005846 -0 -1.5708</pose>
        <geometry>
          <mesh>
            <scale>1 1 1</scale>
            <uri>model://Mobile_Leveling_Platform_V2/meshes/upper.STL</uri>
          </mesh>
        </geometry>
      </visual>
      <visual name='upper_motor_rev_link_fixed_joint_lump__beacon_visual_visual_2'>
        <pose frame=''>0.003251 0.788 0.023982 -0.005846 -0 -1.5708</pose>
        <geometry>
          <box>
            <size>0.1 0.1 0.02</size>
          </box>
        </geometry>
      </visual>
      <visual name='upper_motor_rev_link_fixed_joint_lump__imu_link_upper_visual_3'>
        <pose frame=''>0.002993 0.788817 -0.020018 -0.005846 -0 -1.5708</pose>
        <geometry>
          <box>
            <size>0.01 0.01 0.01</size>
          </box>
        </geometry>
      </visual>
      <gravity>1</gravity>
      <velocity_decay/>
    </link>
    <joint name='upper_motor_rev_joint' type='revolute'>
      <child>upper_motor_rev_link</child>
      <parent>front_motor_rev_link</parent>
      <axis>
        <xyz>1 4e-06 -0</xyz>
        <limit>
          <lower>-0.5236</lower>
          <upper>0.5236</upper>
          <effort>1</effort>
          <velocity>1</velocity>
        </limit>
        <dynamics>
          <spring_reference>0</spring_reference>
          <spring_stiffness>0</spring_stiffness>
        </dynamics>
        <use_parent_model_frame>1</use_parent_model_frame>
      </axis>
    </joint>
    <link name='rear_L_motor_rev_link'>
      <pose frame=''>0.363 0.3731 -0.041791 3.14159 -1.57079 3.14159</pose>
      <inertial>
        <pose frame=''>0 0 -0.010725 0 -0 0</pose>
        <mass>3.03082</mass>
        <inertia>
          <ixx>0.0156335</ixx>
          <ixy>6.36247e-07</ixy>
          <ixz>-5.7378e-07</ixz>
          <iyy>0.0156294</iyy>
          <iyz>-1.7765e-07</iyz>
          <izz>0.0290559</izz>
        </inertia>
      </inertial>
      <collision name='rear_L_motor_rev_link_collision'>
        <pose frame=''>0 0 0 0 -0 0</pose>
        <geometry>
          <mesh>
            <scale>1 1 1</scale>
            <uri>model://Mobile_Leveling_Platform_V2/meshes/rear_L_motor_rev_link.STL</uri>
          </mesh>
        </geometry>
      </collision>
      <collision name='rear_L_motor_rev_link_fixed_joint_lump__rear_L_tire_link_collision_1'>
        <pose frame=''>0 0 -0.011 3.14159 -1.57079 -3.00622</pose>
        <geometry>
          <mesh>
            <scale>1 1 1</scale>
            <uri>model://Mobile_Leveling_Platform_V2/meshes/rear_L_tire_link.STL</uri>
          </mesh>
        </geometry>
      </collision>
      <visual name='rear_L_motor_rev_link_visual'>
        <pose frame=''>0 0 0 0 -0 0</pose>
        <geometry>
          <mesh>
            <scale>1 1 1</scale>
            <uri>model://Mobile_Leveling_Platform_V2/meshes/rear_L_motor_rev_link.STL</uri>
          </mesh>
        </geometry>
      </visual>
      <visual name='rear_L_motor_rev_link_fixed_joint_lump__rear_L_tire_link_visual_1'>
        <pose frame=''>0 0 -0.011 3.14159 -1.57079 -3.00622</pose>
        <geometry>
          <mesh>
            <scale>1 1 1</scale>
            <uri>model://Mobile_Leveling_Platform_V2/meshes/rear_L_tire_link.STL</uri>
          </mesh>
        </geometry>
      </visual>
    </link>
    <joint name='rear_L_motor_rev_joint' type='revolute'>
      <child>rear_L_motor_rev_link</child>
      <parent>base_link</parent>
      <axis>
        <xyz>1 0 4e-06</xyz>
        <limit>
          <lower>-1e+16</lower>
          <upper>1e+16</upper>
        </limit>
        <dynamics>
          <spring_reference>0</spring_reference>
          <spring_stiffness>0</spring_stiffness>
        </dynamics>
        <use_parent_model_frame>1</use_parent_model_frame>
      </axis>
    </joint>
    <link name='rear_R_motor_rev_link'>
      <pose frame=''>-0.363 0.3731 -0.041791 7e-06 -1.57079 -3.14159</pose>
      <inertial>
        <pose frame=''>0 0 -0.010725 0 -0 0</pose>
        <mass>3.03082</mass>
        <inertia>
          <ixx>0.0156335</ixx>
          <ixy>-4.49427e-07</ixy>
          <ixz>-5.7378e-07</ixz>
          <iyy>0.0156294</iyy>
          <iyz>-1.7765e-07</iyz>
          <izz>0.0290559</izz>
        </inertia>
      </inertial>
      <collision name='rear_R_motor_rev_link_collision'>
        <pose frame=''>0 0 0 0 -0 0</pose>
        <geometry>
          <mesh>
            <scale>1 1 1</scale>
            <uri>model://Mobile_Leveling_Platform_V2/meshes/rear_R_motor_rev_link.STL</uri>
          </mesh>
        </geometry>
      </collision>
      <collision name='rear_R_motor_rev_link_fixed_joint_lump__rear_R_tire_link_collision_1'>
        <pose frame=''>0 0 -0.011 3.14159 1.57079 3.00209</pose>
        <geometry>
          <mesh>
            <scale>1 1 1</scale>
            <uri>model://Mobile_Leveling_Platform_V2/meshes/rear_R_tire_link.STL</uri>
          </mesh>
        </geometry>
      </collision>
      <visual name='rear_R_motor_rev_link_visual'>
        <pose frame=''>0 0 0 0 -0 0</pose>
        <geometry>
          <mesh>
            <scale>1 1 1</scale>
            <uri>model://Mobile_Leveling_Platform_V2/meshes/rear_R_motor_rev_link.STL</uri>
          </mesh>
        </geometry>
      </visual>
      <visual name='rear_R_motor_rev_link_fixed_joint_lump__rear_R_tire_link_visual_1'>
        <pose frame=''>0 0 -0.011 3.14159 1.57079 3.00209</pose>
        <geometry>
          <mesh>
            <scale>1 1 1</scale>
            <uri>model://Mobile_Leveling_Platform_V2/meshes/rear_R_tire_link.STL</uri>
          </mesh>
        </geometry>
      </visual>
    </link>
    <joint name='rear_R_motor_rev_joint' type='revolute'>
      <child>rear_R_motor_rev_link</child>
      <parent>base_link</parent>
      <axis>
        <xyz>1 7e-06 4e-06</xyz>
        <limit>
          <lower>-1e+16</lower>
          <upper>1e+16</upper>
        </limit>
        <dynamics>
          <spring_reference>0</spring_reference>
          <spring_stiffness>0</spring_stiffness>
        </dynamics>
        <use_parent_model_frame>1</use_parent_model_frame>
      </axis>
    </joint>
  </model>
</sdf>
